An exception is raised in a routine which is being called as part of
the evaluation of an assertion.  The routine handles the exception
itself and retries it.  Subsequent calls from the "retrying"
invocation of the routine monitor assertions, but should not.

Discovered in Release 3.2.4.
